<?xml version="1.0" encoding="utf-8"?>
<!-- This URDF was automatically created by SolidWorks to URDF Exporter! Originally created by Stephen Brawner (brawner@gmail.com) 
     Commit Version: 1.5.0-0-g9aa0fdb  Build Version: 1.5.7004.21443
     For more information, please see http://wiki.ros.org/sw_urdf_exporter -->
<robot
  name="Testbot">
  <link
    name="base_link">
    <inertial>
      <origin
        xyz="-0.023068 0.007138 0.10009"
        rpy="0 0 0" />
      <mass
        value="0.30113" />
      <inertia
        ixx="0.0002899"
        ixy="-1.9455E-10"
        ixz="9.7425E-11"
        iyy="0.00018178"
        iyz="9.3082E-07"
        izz="0.00039052" />
    </inertial>
    <visual>
      <origin
        xyz="0 0 0"
        rpy="0 0 0" />
      <geometry>
        <mesh
          filename="package://Testbot/meshes/base_link.STL" />
      </geometry>
      <material
        name="">
        <color
          rgba="1 1 1 1" />
      </material>
    </visual>
    <collision>
      <origin
        xyz="0 0 0"
        rpy="0 0 0" />
      <geometry>
        <mesh
          filename="package://Testbot/meshes/base_link.STL" />
      </geometry>
    </collision>
  </link>
  <link
    name="Wheel1">
    <inertial>
      <origin
        xyz="0 0 0.005"
        rpy="0 0 0" />
      <mass
        value="0.0145669368161652" />
      <inertia
        ixx="1.57808482175122E-06"
        ixy="0"
        ixz="1.12828432537139E-22"
        iyy="1.57808482175122E-06"
        iyz="-8.15708456430406E-23"
        izz="2.91338736323303E-06" />
    </inertial>
    <visual>
      <origin
        xyz="0 0 0"
        rpy="0 0 0" />
      <geometry>
        <mesh
          filename="package://Testbot/meshes/Wheel1.STL" />
      </geometry>
      <material
        name="">
        <color
          rgba="0.298039215686275 0.298039215686275 0.298039215686275 1" />
      </material>
    </visual>
    <collision>
      <origin
        xyz="0 0 0"
        rpy="0 0 0" />
      <geometry>
        <mesh
          filename="package://Testbot/meshes/Wheel1.STL" />
      </geometry>
    </collision>
  </link>
  <joint
    name="Wheel1"
    type="continuous">
    <origin
      xyz="0.014432 -0.094041 -0.027305"
      rpy="1.5708 0.085704 1.5708" />
    <parent
      link="base_link" />
    <child
      link="Wheel1" />
    <axis
      xyz="0 0 1" />
    <safety_controller
      k_velocity="0" />
  </joint>
  <link
    name="Wheel2">
    <inertial>
      <origin
        xyz="-1.38777878078145E-17 -3.46944695195361E-18 -0.00500000000000002"
        rpy="0 0 0" />
      <mass
        value="0.0145669368161651" />
      <inertia
        ixx="1.57808482175122E-06"
        ixy="-1.98523347012727E-23"
        ixz="8.47163593494317E-23"
        iyy="1.57808482175122E-06"
        iyz="1.39009859184644E-22"
        izz="2.91338736323303E-06" />
    </inertial>
    <visual>
      <origin
        xyz="0 0 0"
        rpy="0 0 0" />
      <geometry>
        <mesh
          filename="package://Testbot/meshes/Wheel2.STL" />
      </geometry>
      <material
        name="">
        <color
          rgba="0.298039215686275 0.298039215686275 0.298039215686275 1" />
      </material>
    </visual>
    <collision>
      <origin
        xyz="0 0 0"
        rpy="0 0 0" />
      <geometry>
        <mesh
          filename="package://Testbot/meshes/Wheel2.STL" />
      </geometry>
    </collision>
  </link>
  <joint
    name="Wheel2"
    type="continuous">
    <origin
      xyz="-0.060568 -0.094041 -0.027305"
      rpy="1.5708 -0.038116 1.5708" />
    <parent
      link="base_link" />
    <child
      link="Wheel2" />
    <axis
      xyz="0 0 1" />
    <safety_controller
      k_velocity="0" />
  </joint>
  <link
    name="Lidar">
    <inertial>
      <origin
        xyz="-3.46944695195361E-18 0 0.005"
        rpy="0 0 0" />
      <mass
        value="0.00989601685880784" />
      <inertia
        ixx="6.39117755464673E-07"
        ixy="3.30872245021211E-24"
        ixz="-1.23581315856884E-23"
        iyy="6.39117755464673E-07"
        iyz="1.06892914504879E-25"
        izz="1.11330189661588E-06" />
    </inertial>
    <visual>
      <origin
        xyz="0 0 0"
        rpy="0 0 0" />
      <geometry>
        <mesh
          filename="package://Testbot/meshes/Lidar.STL" />
      </geometry>
      <material
        name="">
        <color
          rgba="0.298039215686275 0.298039215686275 0.298039215686275 1" />
      </material>
    </visual>
    <collision>
      <origin
        xyz="0 0 0"
        rpy="0 0 0" />
      <geometry>
        <mesh
          filename="package://Testbot/meshes/Lidar.STL" />
      </geometry>
    </collision>
  </link>
  <joint
    name="Lidar"
    type="continuous">
    <origin
      xyz="-0.023007 -0.12 -0.022638"
      rpy="1.5708 -0.039889 0" />
    <parent
      link="base_link" />
    <child
      link="Lidar" />
    <axis
      xyz="0 0 1" />
    <safety_controller
      k_velocity="0" />
  </joint>
</robot>