<?xml version="1.0"?>
<robot name="oparm" xmlns:xacro="http://ros.org/wiki/xacro">

  <!-- Import RViz colors -->
  <xacro:include filename="$(find oparm_description)/urdf/materials.xacro"/>
  <!-- Import Gazebo settings -->
  <xacro:include filename="$(find oparm_description)/urdf/oparm.gazebo.xacro"/>

  <!-- Transmission macro -->
  <xacro:macro name="SimpleTransmission" params="joint n">
    <transmission name="tran${n}">
      <type>transmission_interface/SimpleTransmission</type>
      <joint name="${joint}">
        <hardwareInterface>hardware_interface/EffortJointInterface</hardwareInterface>
      </joint>
      <actuator name="motor${n}">
        <hardwareInterface>hardware_interface/EffortJointInterface</hardwareInterface>
        <mechanicalReduction>1</mechanicalReduction>
      </actuator>
    </transmission>
  </xacro:macro>

  <!-- World -->
  <link name="world">
  </link>

  <!-- World fixed joint -->
  <joint name="world_fixed" type="fixed">
    <origin xyz="0 0 0" rpy="0 0 0"/>
    <parent link="world"/>
    <child link="base"/>
  </joint>

  <!-- Base -->
  <link name="base">
    <visual>
      <origin xyz="0 0 0" rpy="0 0 0"/>
        <geometry>
          <mesh filename="package://oparm_description/meshes/base.stl" scale="0.001 0.001 0.001"/>
        </geometry>
        <material name="white"/>
    </visual>

    <collision>
      <origin xyz="0 0 0" rpy="0 0 0"/>
      <geometry>
        <mesh filename="package://oparm_description/meshes/base.stl" scale="0.001 0.001 0.001"/>
      </geometry>
    </collision>

    <inertial>
      <origin xyz="0.0 0.0 4.25e-03"/>
      <mass value="1.1846356e-01"/>
      <inertia ixx="2.5025428e-04" ixy="0.0" ixz="0.0"
               iyy="1.2584039e-04" iyz="0.0"
               izz="1.2584039e-04"/>
    </inertial>
  </link>

  <!-- Joint 1 -->
  <joint name="joint1" type="revolute">
    <parent link="base"/>
    <child link="link1"/>
    <origin xyz="0 0 0.0085" rpy="0 0 0"/>
    <axis xyz="0 0 1"/>
    <limit effort="1" velocity="1" lower="${-pi}" upper="${pi}"/>
  </joint>

  <!-- Transmission 1 -->
  <xacro:SimpleTransmission n="1" joint="joint1"/>

  <!-- Link 1 -->
  <link name="link1">
    <visual>
      <origin xyz="0 0 0" rpy="0 0 0"/>
      <geometry>
         <mesh filename="package://oparm_description/meshes/link1.stl" scale="0.001 0.001 0.001"/>
      </geometry>
      <material name="orange"/>
    </visual>

    <collision>
      <origin xyz="0 0 0" rpy="0 0 0"/>
      <geometry>
        <mesh filename="package://oparm_description/meshes/link1.stl" scale="0.001 0.001 0.001"/>
      </geometry>
    </collision>

    <inertial>
      <origin xyz="0.0 0.0 3.9684358e-02"/>
      <mass value="4.2165803e-01"/>
      <inertia ixx="5.7833699e-04" ixy="0.0" ixz="0.0"
               iyy="4.3337111e-04" iyz="0.0"
               izz="3.1986899e-04"/>
    </inertial>
  </link>

  <!-- Joint 2 -->
  <joint name="joint2" type="revolute">
    <parent link="link1"/>
    <child link="link2"/>
    <origin xyz="0 0 0.06" rpy="0 0 0"/>
    <axis xyz="1 0 0"/>
    <limit effort="1" velocity="1" lower="-1.57" upper="1.57"/>
  </joint>

  <!-- Transmission 2 -->
  <xacro:SimpleTransmission n="2" joint="joint2"/>

  <!-- Link 2 -->
  <link name="link2">
    <visual>
      <origin xyz="0 0 0" rpy="0 0 0"/>
      <geometry>
         <mesh filename="package://oparm_description/meshes/link2.stl" scale="0.001 0.001 0.001"/>
      </geometry>
      <material name="green"/>
    </visual>

    <collision>
      <origin xyz="0 0 0" rpy="0 0 0"/>
      <geometry>
        <mesh filename="package://oparm_description/meshes/link2.stl" scale="0.001 0.001 0.001"/>
      </geometry>
    </collision>

    <inertial>
      <origin xyz="0.0 0.0 1.0033384e-01"/>
      <mass value="8.4958426e-01"/>
      <inertia ixx="3.1351289e-03" ixy="0.0" ixz="0.0"
               iyy="3.8828211e-03" iyz="0.0"
               izz="1.0956725e-03"/>
    </inertial>
  </link>

  <!-- Joint 3 -->
  <joint name="joint3" type="revolute">
    <parent link="link2"/>
    <child link="link3"/>
    <origin xyz="0 0 0.215" rpy="0 0 0"/>
    <axis xyz="1 0 0"/>
    <limit effort="1" velocity="1" lower="-1.75" upper="1.75"/>
  </joint>

  <!-- Transmission 3 -->
  <xacro:SimpleTransmission n="3" joint="joint3"/>

  <!-- Link 3 -->
  <link name="link3">
    <visual>
      <origin xyz="0 0 0" rpy="0 0 0"/>
      <geometry>
         <mesh filename="package://oparm_description/meshes/link3.stl" scale="0.001 0.001 0.001"/>
      </geometry>
      <material name="blue"/>
    </visual>

    <collision>
      <origin xyz="0 0 0" rpy="0 0 0"/>
      <geometry>
        <mesh filename="package://oparm_description/meshes/link3.stl" scale="0.001 0.001 0.001"/>
      </geometry>
    </collision>

    <inertial>
      <origin xyz="0.0 0.0 2.3397032e-02"/>
      <mass value="2.2194839e-01"/>
      <inertia ixx="1.9511023e-04" ixy="0.0" ixz="0.0"
               iyy="1.9779470e-04" iyz="0.0"
               izz="8.3472948e-05"/>
    </inertial>
  </link>

  <!-- Joint 4 -->
  <joint name="joint4" type="revolute">
    <parent link="link3"/>
    <child link="link4"/>
    <origin xyz="0 0 0.085" rpy="0 0 0"/>
    <axis xyz="0 0 1"/>
    <limit effort="1" velocity="1" lower="${-pi}" upper="${pi}"/>
  </joint>

  <!-- Transmission 4 -->
  <xacro:SimpleTransmission n="4" joint="joint4"/>

  <!-- Link 4 -->
  <link name="link4">
    <visual>
      <origin xyz="0 0 0" rpy="0 0 0"/>
      <geometry>
         <mesh filename="package://oparm_description/meshes/link4.stl" scale="0.001 0.001 0.001"/>
      </geometry>
      <material name="pink"/>
    </visual>

    <collision>
      <origin xyz="0 0 0" rpy="0 0 0"/>
      <geometry>
        <mesh filename="package://oparm_description/meshes/link4.stl" scale="0.001 0.001 0.001"/>
      </geometry>
    </collision>

    <inertial>
      <origin xyz="0.0 0.0 3.7163357e-02"/>
      <mass value="2.9812125e-01"/>
      <inertia ixx="2.3173010e-04" ixy="0.0" ixz="0.0"
               iyy="3.7059083e-04" iyz="0.0"
               izz="2.6307792e-04"/>
    </inertial>
  </link>

  <!-- Joint 5-->
  <joint name="joint5" type="revolute">
    <parent link="link4"/>
    <child link="link5"/>
    <origin xyz="0 0 0.0725" rpy="0 0 0"/>
    <axis xyz="1 0 0"/>
    <limit effort="1" velocity="1" lower="-1.57" upper="1.57"/>
  </joint>

  <!-- Transmission 5 -->
  <xacro:SimpleTransmission n="5" joint="joint5"/>

  <!-- Link 5 -->
  <link name="link5">
    <visual>
      <origin xyz="0 0 0" rpy="0 0 0"/>
      <geometry>
         <mesh filename="package://oparm_description/meshes/link5.stl" scale="0.001 0.001 0.001"/>
      </geometry>
      <material name="red"/>
    </visual>

    <collision>
      <origin xyz="0 0 0" rpy="0 0 0"/>
      <geometry>
        <mesh filename="package://oparm_description/meshes/link5.stl" scale="0.001 0.001 0.001"/>
      </geometry>
    </collision>

    <inertial>
      <origin xyz="0.0 0.0 1.8350632e-02"/>
      <mass value="1.2109134e-01"/>
      <inertia ixx="6.6737478e-05" ixy="0.0" ixz="0.0"
               iyy="6.7027298e-05" iyz="0.0"
               izz="3.9548898e-05"/>
    </inertial>
  </link>
  
</robot>
