<?xml version="1.0" ?>

<robot name="oparm" xmlns:xacro="http://www.ros.org/wiki/xacro">
    <link name="oparm_base">
        <visual>
            <origin xyz="0 0 0" rpy="0 0 0"/>
            <geometry>
                <mesh filename="package://oparm_description/meshes/oparm_base.dae"/>
            </geometry>
        </visual>
    </link>

    <joint name="oparm_base_oparm_link01_joint" type="revolute">
        <parent link="oparm_base"/>
        <child link="oparm_link01"/>
        <origin xyz="0 0 0.0085" rpy="0 0 0"/>
        <axis xyz="0 0 1"/>
        <limit effort="30" lower="-3.14" upper="3.14" velocity="1.571"/>
    </joint>

    <link name="oparm_link01">
        <visual>
            <origin xyz="0 0 0.0" rpy="0 0 0"/>
            <geometry>
                <mesh filename="package://oparm_description/meshes/oparm_link01.dae"/>
            </geometry>
        </visual>
    </link>
    <joint name="oparm_link01_oparm_link02_joint" type="revolute">
        <parent link="oparm_link01"/>
        <child link="oparm_link02"/>
        <origin xyz="0 0 0.06" rpy="0 0 0"/>
        <axis xyz="1 0 0"/>
        <limit effort="30" lower="-1.744444444" upper="1.744444444" velocity="1.571"/>
    </joint>

    <link name="oparm_link02">
        <visual>
            <origin xyz="0 0 0.0" rpy="0 0 0"/>
            <geometry>
                <mesh filename="package://oparm_description/meshes/oparm_link02.dae"/>
            </geometry>
        </visual>
    </link>

    <joint name="oparm_link02_oparm_link03_joint" type="revolute">
        <parent link="oparm_link02"/>
        <child link="oparm_link03"/>
        <origin xyz="0 0 0.215" rpy="0 0 0"/>
        <axis xyz="1 0 0"/>
        <limit effort="30" lower="-2.267777778" upper="2.267777778" velocity="1.571"/>
    </joint>

    <link name="oparm_link03">
        <visual>
            <origin xyz="0 0 0.0" rpy="0 0 0"/>
            <geometry>
                <mesh filename="package://oparm_description/meshes/oparm_link03.dae"/>
            </geometry>
        </visual>
    </link>

    <joint name="oparm_link03_oparm_link04_joint" type="revolute">
        <parent link="oparm_link03"/>
        <child link="oparm_link04"/>
        <origin xyz="0 0 0.085" rpy="0 0 0"/>
        <axis xyz="0 0 1"/>
        <limit effort="30" lower="-3.14" upper="3.14" velocity="1.571"/>
    </joint>

    <link name="oparm_link04">
        <visual>
            <origin xyz="0 0 0.0" rpy="0 0 0"/>
            <geometry>
                <mesh filename="package://oparm_description/meshes/oparm_link04.dae"/>
            </geometry>
        </visual>
    </link>

    <joint name="oparm_link04_oparm_link05_joint" type="revolute">
        <parent link="oparm_link04"/>
        <child link="oparm_link05"/>
        <origin xyz="0 0 0.0725" rpy="0 0 0"/>
        <axis xyz="1 0 0"/>
        <limit effort="30" lower="-1.744444444" upper="1.744444444" velocity="1.571"/>
    </joint>

    <link name="oparm_link05">
        <visual>
            <origin xyz="0 0 0.0" rpy="0 0 0"/>
            <geometry>
                <mesh filename="package://oparm_description/meshes/oparm_link05.dae"/>
            </geometry>
        </visual>
    </link>
</robot>